<?xml version="1.0"?>
<robot name="three_dof_arm" xmlns:xacro="http://ros.org/wiki/xacro">

  <!-- Include materials -->
  <material name="Black">
    <color rgba="0.0 0.0 0.0 1.0"/>
  </material>
  <material name="Red">
    <color rgba="0.8 0.0 0.0 1.0"/>
  </material>
  <material name="White">
    <color rgba="1.0 1.0 1.0 1.0"/>
  </material>

  <xacro:property name="deg_to_rad" value="0.01745329251994329577"/>

  <!-- Constants -->
  <xacro:property name="M_SCALE" value="0.001 0.001 0.001"/> 
  <xacro:property name="M_PI" value="3.14159"/>

  <!-- Shoulder pan link properties -->
  <xacro:property name="shoulder_pan_width" value="0.04" />
  <xacro:property name="shoulder_pan_len" value="0.08" />

  <!-- Shoulder pitch link properties -->
  <xacro:property name="shoulder_pitch_len" value="0.14" />
  <xacro:property name="shoulder_pitch_width" value="0.04" />
  <xacro:property name="shoulder_pitch_height" value="0.04" />

  <!-- Elbow roll link properties -->
  <xacro:property name="elbow_roll_width" value="0.02" />
  <xacro:property name="elbow_roll_len" value="0.06" />

  <!-- Elbow pitch link properties -->
  <xacro:property name="elbow_pitch_len" value="0.22" />
  <xacro:property name="elbow_pitch_width" value="0.04" />
  <xacro:property name="elbow_pitch_height" value="0.04" />
  
<xacro:macro name="inertial_matrix" params="mass">
      <inertial>
      	<mass value="${mass}" />
        <inertia ixx="1.0" ixy="0.0" ixz="0.0" iyy="0.5" iyz="0.0" izz="1.0" />
      </inertial>
   </xacro:macro>

   <xacro:macro name="transmission_block" params="joint_name">
	  <transmission name="tran1">
	    <type>transmission_interface/SimpleTransmission</type>
	    <joint name="${joint_name}">
	      <hardwareInterface>hardware_interface/PositionJointInterface</hardwareInterface>
	    </joint>
	    <actuator name="motor1">
	      <hardwareInterface>hardware_interface/PositionJointInterface</hardwareInterface>
	      <mechanicalReduction>1</mechanicalReduction>
	    </actuator>
	  </transmission>
   </xacro:macro>
   
  <!-- Define bottom link -->
  <link name="bottom_link">
    <visual>
      <origin xyz=" 0 0 -0.04"  rpy="0 0 0"/>
      <geometry>
        <box size="1 1 0.02" />
      </geometry>
      <material name="Brown" />
    </visual>
    <collision>
      <origin xyz=" 0 0 -0.04"  rpy="0 0 0"/>
      <geometry>
        <box size="1 1 0.02" />
      </geometry>
    </collision>
  </link>

  <!-- Define base link -->
  <link name="base_link">
    <visual>
      <origin xyz="0 0 0" rpy="${M_PI/2} 0 0" /> <!-- rotate PI/2 -->
      <geometry>
        <box size="0.1 0.1 0.1" />
      </geometry>
      <material name="White" />
    </visual>
    <collision>
      <origin xyz="0 0 0" rpy="${M_PI/2} 0 0" /> <!-- rotate PI/2 -->
      <geometry>
        <box size="0.1 0.1 0.1" />
      </geometry>
    </collision>
    <inertial>
      <mass value="1"/>
      <inertia ixx="1.0" ixy="0.0" ixz="0.0" iyy="0.5" iyz="0.0" izz="1.0" />
    </inertial>
  </link>

  <!-- Joint definitions -->
  <joint name="bottom_joint" type="fixed">
    <origin xyz="0 0 0" rpy="0 0 0" />
    <parent link="base_link"/>
    <child link="bottom_link"/>
  </joint>

  <joint name="shoulder_pan_joint" type="revolute">
    <parent link="base_link"/>
    <child link="shoulder_pan_link"/>
    <origin xyz="0 0 0.05" rpy="0 ${M_PI/2} ${M_PI*0}" />
    <axis xyz="-1 0 0" />
    <limit effort="300" velocity="1" lower="-2.61799387799" upper="1.98394848567"/>
    <dynamics damping="50" friction="1"/>
  </joint>

  <joint name="shoulder_pitch_joint" type="revolute">
    <parent link="shoulder_pan_link"/>
    <child link="shoulder_pitch_link"/>
    <origin xyz="-0.041 0.0021 0.0" rpy="-${M_PI/2} 0 ${M_PI/2}" />
    <axis xyz="1 0 0" />
    <limit effort="300" velocity="1" lower="-1.19962513147" upper="1.89994105047" />
    <dynamics damping="50" friction="1"/>
  </joint>

  <joint name="elbow_roll_joint" type="fixed">
    <parent link="shoulder_pitch_link"/>
    <child link="elbow_roll_link"/>
    <origin xyz="-0.002 0 0.1206" rpy="${M_PI} ${M_PI/2} 0" />
    <axis xyz="-1 0 0" />
    <!-- Remove limit, dynamics, and transmission for fixed joint -->
  </joint>


  <joint name="elbow_pitch_joint" type="revolute">
    <parent link="elbow_roll_link"/>
    <child link="elbow_pitch_link"/>
    <origin xyz="-0.035 0 0.0" rpy="0.055 ${M_PI/2} 0" />
    <axis xyz="1 0 0" />
    <limit effort="300" velocity="1" lower="-1.5953400194" upper="1.93281579274" />
    <dynamics damping="50" friction="1"/>
  </joint>
 
  <!-- Links and visuals for the shoulder pan and pitch links -->

  <!-- SHOULDER PAN LINK -->
  <link name="shoulder_pan_link">
    <visual>
      <origin xyz="0 0 0" rpy="0 ${M_PI/2} 0" />
      <geometry>
        <cylinder radius="${shoulder_pan_width}" length="${shoulder_pan_len}"/>
      </geometry>
      <material name="Red" />
    </visual>
    <collision>
      <origin xyz="0 0 0" rpy="0 ${M_PI/2} 0" />
      <geometry>
        <cylinder radius="${shoulder_pan_width}" length="${shoulder_pan_len}"/>
      </geometry>
    </collision>
    <inertial>
      <mass value="1"/>
      <inertia ixx="1.0" ixy="0.0" ixz="0.0" iyy="0.5" iyz="0.0" izz="1.0" />
    </inertial>
  </link>

  <!-- SHOULDER PITCH LINK -->
  <link name="shoulder_pitch_link">
    <visual>
      <origin xyz="-0.002 0 0.04" rpy="0 ${M_PI/2} 0" />
      <geometry>
        <box size="${shoulder_pitch_len} ${shoulder_pitch_width} ${shoulder_pitch_height}" />
      </geometry>
      <material name="White" />
    </visual>
    <collision>
      <origin xyz="-0.002 0 0.04" rpy="0 ${M_PI/2} 0" />
      <geometry>
        <box size="${shoulder_pitch_len} ${shoulder_pitch_width} ${shoulder_pitch_height}" />
      </geometry>
    </collision>
    <inertial>
      <mass value="1"/>
      <inertia ixx="1.0" ixy="0.0" ixz="0.0" iyy="0.5" iyz="0.0" izz="1.0" />
    </inertial>
  </link>

  <!-- ELBOW ROLL LINK -->
  <link name="elbow_roll_link" >
    <visual>
      <origin xyz="-0.015 0.0 -0.0" rpy="0 ${M_PI/2} 0" />
      <geometry>
           <cylinder radius="${elbow_roll_width}" length="${elbow_roll_len}"/>
      </geometry>
      <material name="Black" />
    </visual>
    <collision>
      <origin xyz="-0.015 0.0 -0.0" rpy="0 ${M_PI/2} 0" />
      <geometry>
            <cylinder radius="${elbow_roll_width}" length="${elbow_roll_len}"/>
      </geometry>
    </collision>
	      <xacro:inertial_matrix mass="1"/>
  </link>

  <!-- ELBOW PITCH LINK -->
  <link name="elbow_pitch_link" >

    <visual>
      <origin xyz="0 0 -0.12" rpy="0 ${M_PI/2} 0" />
      <geometry>

       <box size="${elbow_pitch_len} ${elbow_pitch_width} ${elbow_pitch_height}" />
	
      </geometry>
      <material name="Red" />
    </visual>

    <collision>
      <origin xyz="0 0 -0.12" rpy="0 ${M_PI/2} 0" />
      <geometry>
       <box size="${elbow_pitch_len} ${elbow_pitch_width} ${elbow_pitch_height}" />
      </geometry>
    </collision>
	      <xacro:inertial_matrix mass="1"/>
  </link>

  <!-- Transmissions for ROS Control -->
  <transmission name="tran1">
    <type>transmission_interface/SimpleTransmission</type>
    <joint name="shoulder_pan_joint">
      <hardwareInterface>hardware_interface/PositionJointInterface</hardwareInterface>
    </joint>
    <actuator name="motor1">
      <hardwareInterface>hardware_interface/PositionJointInterface</hardwareInterface>
      <mechanicalReduction>1</mechanicalReduction>
    </actuator>
  </transmission>

  <transmission name="tran2">
    <type>transmission_interface/SimpleTransmission</type>
    <joint name="shoulder_pitch_joint">
      <hardwareInterface>hardware_interface/PositionJointInterface</hardwareInterface>
    </joint>
    <actuator name="motor2">
      <hardwareInterface>hardware_interface/PositionJointInterface</hardwareInterface>
      <mechanicalReduction>1</mechanicalReduction>
    </actuator>
  </transmission>

  <!-- <transmission name="tran3">
    <type>transmission_interface/SimpleTransmission</type>
    <joint name="elbow_roll_joint">
      <hardwareInterface>hardware_interface/PositionJointInterface</hardwareInterface>
    </joint>
    <actuator name="motor3">
      <hardwareInterface>hardware_interface/PositionJointInterface</hardwareInterface>
      <mechanicalReduction>1</mechanicalReduction>
    </actuator>
  </transmission> -->

  <transmission name="tran4">
    <type>transmission_interface/SimpleTransmission</type>
    <joint name="elbow_pitch_joint">
      <hardwareInterface>hardware_interface/PositionJointInterface</hardwareInterface>
    </joint>
    <actuator name="motor4">
      <hardwareInterface>hardware_interface/PositionJointInterface</hardwareInterface>
      <mechanicalReduction>1</mechanicalReduction>
    </actuator>
  </transmission>


  <!-- Include gazebo plugin for ROS Control -->
  <gazebo>
    <plugin name="gazebo_ros_control" filename="libgazebo_ros_control.so">
      <robotNamespace>/three_dof_arm</robotNamespace>
    </plugin>
  </gazebo>

</robot>
 